<?xml version="1.0" ?>
<!-- =================================================================================== -->
<!-- |    This document was autogenerated by xacro from model.xacro                    | -->
<!-- |    EDITING THIS FILE BY HAND IS NOT RECOMMENDED                                 | -->
<!-- =================================================================================== -->
<robot name="ackerma_robot">
  <plugin filename="gz-sim-diff-drive-system" name="gz::sim::systems::DiffDrive">
    <left_joint>left_wheel_joint</left_joint>
    <right_joint>right_wheel_joint</right_joint>
    <wheel_separation>1.2</wheel_separation>
    <wheel_radius>0.4</wheel_radius>
    <odom_publish_frequency>1</odom_publish_frequency>
    <topic>cmd_vel</topic>
  </plugin>
  <!-- Links -->
  <!-- Body Link -->
  <link name="body_link">
    <visual>
      <origin rpy="0.0 0.0 0.0" xyz="0.0 0.0 0.0"/>
      <geometry>
        <box size="2.0 1.0 0.5"/>
      </geometry>
      <material name="body_material">
        <color rgba="0.25 0.25 0.25 1.0"/>
      </material>
    </visual>
    <collision>
      <origin rpy="0.0 0.0 0.0" xyz="0.0 0.0 0.0"/>
      <geometry>
        <box size="2.0 1.0 0.5"/>
      </geometry>
    </collision>
    <inertial>
      <mass value="1000.0"/>
      <inertia ixx="104.16666666666666" ixy="0.0" ixz="0.0" iyy="354.16666666666663" iyz="0" izz="416.66666666666663"/>
      <origin rpy="0 0 0" xyz="0 0 0"/>
    </inertial>
  </link>
  <!-- Front Left Wheel -->
  <link name="front_left_wheel_link">
    <visual>
      <origin rpy="1.570795 0.0 0.0" xyz="0.0 0.0 0.0"/>
      <geometry>
        <cylinder length="0.1" radius="0.3"/>
      </geometry>
      <material name="wheel_material">
        <color rgba="0.0 0.0 0.0 1.0"/>
      </material>
    </visual>
    <collision>
      <origin rpy="1.570795 0.0 0.0" xyz="0.0 0.0 0.0"/>
      <geometry>
        <cylinder length="0.1" radius="0.3"/>
      </geometry>
    </collision>
    <inertial>
      <mass value="28.27433385"/>
      <inertia ixx="0.6597344564999998" ixy="0.0" ixz="0.0" iyy="0.6597344564999998" iyz="0" izz="1.27234502325"/>
      <origin rpy="1.570795 0.0 0.0" xyz="0.0 0.0 0.0"/>
    </inertial>
  </link>
  <!-- Front Left Wheel Steering -->
  <link name="front_left_steering_link">
    <visual>
      <origin rpy="1.570795 0.0 0.0" xyz="0.0 0.0 0.0"/>
      <geometry>
        <cylinder length="0.001" radius="0.01"/>
      </geometry>
      <material name="wheel_material">
        <color rgba="0.0 0.0 0.0 1.0"/>
      </material>
    </visual>
    <collision>
      <origin rpy="1.570795 0.0 0.0" xyz="0.0 0.0 0.0"/>
      <geometry>
        <cylinder length="0.001" radius="0.01"/>
      </geometry>
    </collision>
    <inertial>
      <mass value="0.01"/>
      <inertia ixx="0.0" ixy="0.0" ixz="0.0" iyy="0.0" iyz="0.0" izz="0.0"/>
      <origin rpy="1.570795 0.0 0.0" xyz="0.0 0.0 0.0"/>
    </inertial>
  </link>
  <!-- Front Right Wheel -->
  <link name="front_right_wheel_link">
    <visual>
      <origin rpy="1.570795 0.0 0.0" xyz="0.0 0.0 0.0"/>
      <geometry>
        <cylinder length="0.1" radius="0.3"/>
      </geometry>
      <material name="wheel_material">
        <color rgba="0.0 0.0 0.0 1.0"/>
      </material>
    </visual>
    <collision>
      <origin rpy="1.570795 0.0 0.0" xyz="0.0 0.0 0.0"/>
      <geometry>
        <cylinder length="0.1" radius="0.3"/>
      </geometry>
    </collision>
    <inertial>
      <mass value="28.27433385"/>
      <inertia ixx="0.6597344564999998" ixy="0.0" ixz="0.0" iyy="0.6597344564999998" iyz="0" izz="1.27234502325"/>
      <origin rpy="1.570795 0.0 0.0" xyz="0.0 0.0 0.0"/>
    </inertial>
  </link>
  <!-- Front Right Wheel Steering -->
  <link name="front_right_steering_link">
    <visual>
      <origin rpy="1.570795 0.0 0.0" xyz="0.0 0.0 0.0"/>
      <geometry>
        <cylinder length="0.001" radius="0.01"/>
      </geometry>
      <material name="wheel_material">
        <color rgba="0.0 0.0 0.0 1.0"/>
      </material>
    </visual>
    <collision>
      <origin rpy="1.570795 0.0 0.0" xyz="0.0 0.0 0.0"/>
      <geometry>
        <cylinder length="0.001" radius="0.01"/>
      </geometry>
    </collision>
    <inertial>
      <mass value="0.01"/>
      <inertia ixx="0.0" ixy="0.0" ixz="0.0" iyy="0.0" iyz="0.0" izz="0.0"/>
      <origin rpy="1.570795 0.0 0.0" xyz="0.0 0.0 0.0"/>
    </inertial>
  </link>
  <!-- Rear Left Wheel -->
  <link name="rear_left_wheel_link">
    <visual>
      <origin rpy="1.570795 0.0 0.0" xyz="0.0 0.0 0.0"/>
      <geometry>
        <cylinder length="0.1" radius="0.3"/>
      </geometry>
      <material name="wheel_material">
        <color rgba="0.0 0.0 0.0 1.0"/>
      </material>
    </visual>
    <collision>
      <origin rpy="1.570795 0.0 0.0" xyz="0.0 0.0 0.0"/>
      <geometry>
        <cylinder length="0.1" radius="0.3"/>
      </geometry>
    </collision>
    <inertial>
      <mass value="2"/>
      <inertia ixx="0.6597344564999998" ixy="0.0" ixz="0.0" iyy="0.6597344564999998" iyz="0" izz="1.27234502325"/>
      <origin rpy="1.570795 0.0 0.0" xyz="0.0 0.0 0.0"/>
    </inertial>
  </link>
  <!-- Rear Right Wheel -->
  <link name="rear_right_wheel_link">
    <visual>
      <origin rpy="1.570795 0.0 0.0" xyz="0.0 0.0 0.0"/>
      <geometry>
        <cylinder length="0.1" radius="0.3"/>
      </geometry>
      <material name="wheel_material">
        <color rgba="0.0 0.0 0.0 1.0"/>
      </material>
    </visual>
    <collision>
      <origin rpy="1.570795 0.0 0.0" xyz="0.0 0.0 0.0"/>
      <geometry>
        <cylinder length="0.1" radius="0.3"/>
      </geometry>
    </collision>
    <inertial>
      <mass value="2"/>
      <inertia ixx="0.6597344564999998" ixy="0.0" ixz="0.0" iyy="0.6597344564999998" iyz="0" izz="1.27234502325"/>
      <origin rpy="1.570795 0.0 0.0" xyz="0.0 0.0 0.0"/>
    </inertial>
  </link>
  <!-- Joints -->
  <!-- Front Left Steering Joint -->
  <joint name="front_left_steering_joint" type="revolute">
    <origin rpy="0 0 0" xyz="0.7 0.55 -0.15"/>
    <parent link="body_link"/>
    <child link="front_left_steering_link"/>
    <axis xyz="0 0 1"/>
    <limit effort="1.0" lower="-0.6108" upper="0.6108" velocity="1.570796"/>
    <dynamics damping="0.1" friction="0.1"/>
  </joint>
  <!-- Front Left Wheel Joint -->
  <joint name="front_left_wheel_joint" type="continuous">
    <origin rpy="0 0 0" xyz="0 0 0"/>
    <parent link="front_left_steering_link"/>
    <child link="front_left_wheel_link"/>
    <axis xyz="0 1 0"/>
    <limit effort="10.0" velocity="3.3333333333333335"/>
    <dynamics damping="0.1" friction="0.1"/>
  </joint>
  <!-- Front Right Steering Joint -->
  <joint name="front_right_steering_joint" type="revolute">
    <origin rpy="0 0 0" xyz="0.7 -0.55 -0.15"/>
    <parent link="body_link"/>
    <child link="front_right_steering_link"/>
    <axis xyz="0 0 1"/>
    <limit effort="1.0" lower="-0.6108" upper="0.6108" velocity="1.570796"/>
    <dynamics damping="0.1" friction="0.1"/>
  </joint>
  <!-- Front Right Wheel Joint -->
  <joint name="front_right_wheel_joint" type="continuous">
    <origin rpy="0 0 0" xyz="0 0 0"/>
    <parent link="front_right_steering_link"/>
    <child link="front_right_wheel_link"/>
    <axis xyz="0 1 0"/>
    <limit effort="10.0" velocity="3.3333333333333335"/>
    <dynamics damping="0.1" friction="0.1"/>
  </joint>
  <!-- Rear Left Wheel Joint -->
  <joint name="rear_left_wheel_joint" type="continuous">
    <origin rpy="0 0 0" xyz="-0.7 0.55 -0.15"/>
    <parent link="body_link"/>
    <child link="rear_left_wheel_link"/>
    <axis xyz="0 1 0"/>
    <limit effort="10.0" velocity="3.3333333333333335"/>
    <dynamics damping="0.1" friction="0.1"/>
  </joint>
  <!-- Rear Right Wheel Joint -->
  <joint name="rear_right_wheel_joint" type="continuous">
    <origin rpy="0 0 0" xyz="-0.7 -0.55 -0.15"/>
    <parent link="body_link"/>
    <child link="rear_right_wheel_link"/>
    <axis xyz="0 1 0"/>
    <limit effort="10.0" velocity="3.3333333333333335"/>
    <dynamics damping="0.1" friction="0.1"/>
  </joint>
  <!-- Gazebo Parameters -->
  <gazebo reference="body_link">
    <mu1>0.0001</mu1>
    <mu2>0.0001</mu2>
  </gazebo>
  <gazebo reference="front_right_wheel_link">
    <mu1>100.0</mu1>
    <mu2>100.0</mu2>
  </gazebo>
  <gazebo reference="front_left_wheel_link">
    <mu1>100.0</mu1>
    <mu2>100.0</mu2>
  </gazebo>
  <gazebo reference="rear_right_wheel_link">
    <mu1>100.0</mu1>
    <mu2>100.0</mu2>
  </gazebo>
  <gazebo reference="rear_left_wheel_link">
    <mu1>100.0</mu1>
    <mu2>100.0</mu2>
  </gazebo>
  <!-- Gazebo Control -->
  <ros2_control name="control" type="system">
    <hardware>
      <plugin>gz_ros2_control/GazeboSimSystem</plugin>
    </hardware>
    <joint name="front_left_steering_joint">
      <command_interface name="position">
        <param name="min">-0.6108</param>
        <param name="max">0.6108</param>
      </command_interface>
      <state_interface name="position"/>
      <state_interface name="velocity"/>
      <state_interface name="effort"/>
    </joint>
    <joint name="front_right_steering_joint">
      <command_interface name="position">
        <param name="min">-0.6108</param>
        <param name="max">0.6108</param>
      </command_interface>
      <state_interface name="position"/>
      <state_interface name="velocity"/>
      <state_interface name="effort"/>
    </joint>
    <joint name="rear_left_wheel_joint">
      <command_interface name="velocity">
        <param name="min">-3.3333333333333335</param>
        <param name="max">3.3333333333333335</param>
      </command_interface>
      <state_interface name="position"/>
      <state_interface name="velocity"/>
      <state_interface name="effort"/>
    </joint>
    <joint name="rear_right_wheel_joint">
      <command_interface name="velocity">
        <param name="min">-3.3333333333333335</param>
        <param name="max">3.3333333333333335</param>
      </command_interface>
      <state_interface name="position"/>
      <state_interface name="velocity"/>
      <state_interface name="effort"/>
    </joint>
  </ros2_control>
  <!-- Gazebo Plugins -->
  <gazebo>
    <plugin filename="gz-sim-joint-state-publisher-system" name="gz::sim::systems::JointStatePublisher">
      <topic>joint_states</topic>
      <joint_name>front_left_steering_joint</joint_name>
      <joint_name>front_right_steering_joint</joint_name>
      <joint_name>front_left_wheel_joint</joint_name>
      <joint_name>front_right_wheel_joint</joint_name>
      <joint_name>rear_left_wheel_joint</joint_name>
      <joint_name>rear_right_wheel_joint</joint_name>
    </plugin>
    <!-- Moving Forward -->
    <plugin filename="gz-sim-triggered-publisher-system" name="gz::sim::systems::TriggeredPublisher">
      <input topic="/keyboard/keypress" type="gz.msgs.Int32">
        <match field="data">16777235</match>
      </input>
      <output topic="/cmd_vel" type="gz.msgs.Twist">
		    linear: {x: 0.5}, angular: {z: 0.0}
	    </output>
    </plugin>
    <!-- Moving Backward-->
    <plugin filename="gz-sim-triggered-publisher-system" name="gz::sim::systems::TriggeredPublisher">
      <input topic="/keyboard/keypress" type="gz.msgs.Int32">
        <match field="data">16777237</match>
      </input>
      <output topic="/cmd_vel" type="gz.msgs.Twist">
		    linear: {x: -0.5}, angular: {z: 0}
	    </output>
    </plugin>
    <!-- Moving LEFT-->
    <plugin filename="gz-sim-triggered-publisher-system" name="gz::sim::systems::TriggeredPublisher">
      <input topic="/keyboard/keypress" type="gz.msgs.Int32">
        <match field="data">16777234</match>
      </input>
      <output topic="/cmd_vel" type="gz.msgs.Twist">
		    linear: {x: 0}, angular: {z: 0.5}
	    </output>
    </plugin>
    <!-- Moving RIGHT-->
    <plugin filename="gz-sim-triggered-publisher-system" name="gz::sim::systems::TriggeredPublisher">
      <input topic="/keyboard/keypress" type="gz.msgs.Int32">
        <match field="data">16777236</match>
      </input>
      <output topic="/cmd_vel" type="gz.msgs.Twist">
		    linear: {x: 0}, angular: {z: -0.5}
	    </output>
    </plugin>
  </gazebo>
</robot>
