<?xml version="1.0"?>
<robot name="ackermann_drive" xmlns:xacro="http://ros.org/wiki/xacro">
    <material name="Black">
        <color rgba="0 0 0 1" />
    </material>
    <material name="Grey">
        <color rgba="0.8 0.8 0.8 1" />
    </material>
    <material name="Orange">
        <color rgba="1 0.6 0 1" />
    </material>
    <material name="White">
        <color rgba="1 1 1 1" />
    </material>


    <!-- Define robot constants -->
    <xacro:property name="base_width" value="0.117"/>
    <xacro:property name="base_length" value="0.183"/>
    <xacro:property name="base_height" value="0.05"/>
    <xacro:property name="wheel_radius" value="0.03"/>
    <xacro:property name="wheel_width" value="0.02"/>
    <xacro:property name="wheel_ygap" value="0.025"/>
    <xacro:property name="wheel_zoff" value="0.05"/>
    <xacro:property name="wheel_xoff" value="0.12"/>



    <xacro:arg name="sim_mode" default="false"/>


    <link name="base_link" />

    <!-- Chassis -->
    <link name="chassis">
        <collision>
            <origin xyz="0 0 0" rpy="0 0 0" />
            <geometry>
                <box size="${base_length} ${base_width} ${base_height}" />
            </geometry>
        </collision>

        <visual>
            <origin xyz="0 0 0" rpy="0 0 0" />
            <geometry>
                <box size="${base_length} ${base_width} ${base_height}" />
            </geometry>
            <material name="Orange" />
        </visual>

        <inertial>
            <origin xyz="0 0 0" rpy="0 0 0" />
            <mass value="100" />
            <inertia ixx="1.04" ixy="0.0" ixz="0.0" iyy="3.54" iyz="0.0" izz="4.166" />
        </inertial>
    </link>

    <joint name="chassis_joint" type="fixed">
        <origin xyz="0.8 0 0.1" rpy="0 0 0" />
        <parent link="base_link" />
        <child link="chassis" />
    </joint>

    <!-- rear left wheel Link -->
    <link name="rear_left_wheel">
        <collision>
            <geometry>
                <cylinder length="0.02" radius="0.03" />
            </geometry>
        </collision>
        <visual>
            <geometry>
                <cylinder length="0.02" radius="0.03" />
            </geometry>
            <material name="Black" />
        </visual>

        <inertial>
            <mass value="11.3" />
            <inertia ixx="0.026" ixy="0.0" ixz="0.0" iyy="0.026" iyz="0.0" izz="0.051" />
        </inertial>
    </link>

    <joint name="rear_left_wheel_joint" type="continuous">
        <origin xyz="-0.07 0.06 -0.03" rpy="-1.57 0 0" />
        <parent link="chassis" />
        <child link="rear_left_wheel" />
        <axis xyz="0 0 1" />
        <dynamics damping="0.2" />
    </joint>

    <!-- rear right wheel Link -->
    <link name="rear_right_wheel">
        <collision>
            <geometry>
                <cylinder length="${wheel_width}" radius="${wheel_radius}" />
            </geometry>
        </collision>
        <visual>
            <geometry>
                <cylinder length="${wheel_width}" radius="${wheel_radius}" />
            </geometry>
            <material name="Black" />
        </visual>
        <inertial>
            <mass value="11.3" />
            <inertia ixx="0.026" ixy="0.0" ixz="0.0" iyy="0.026" iyz="0.0" izz="0.051" />
        </inertial>
    </link>

    <joint name="rear_right_wheel_joint" type="continuous">
        <origin xyz="-0.07 -0.06 -0.03" rpy="-1.57 0 0" />
        <parent link="chassis" />
        <child link="rear_right_wheel" />
        <axis xyz="0 0 1" />
        <dynamics damping="0.2" />
    </joint>

   
    <link name="left_wheel_steering">
        <inertial>
            <mass value="0.1"/>
            <inertia ixx="0.26" ixy="0.0" ixz="0.0" iyy="0.26" iyz="0.0" izz="0.51" />
        </inertial>
    </link>

    <joint name="left_wheel_steering_joint" type="revolute">
        <origin xyz="0.07 -0.06 -0.03" rpy="1.57 0 0" />
        <parent link="chassis" />
        <child link="left_wheel_steering" />
        <axis xyz="0 1 0" />
        <dynamics damping="0.2" />
        <limit effort="10000.0" lower="-0.57" upper="0.57" velocity="30"/>
    </joint>

    <link name="right_wheel_steering">
        <inertial>
            <mass value="0.1"/>
            <inertia ixx="0.26" ixy="0.0" ixz="0.0" iyy="0.26" iyz="0.0" izz="0.51" />
        </inertial>
    </link>

    <joint name="right_wheel_steering_joint" type="revolute">
        <origin xyz="0.07 0.06 -0.03" rpy="1.57 0 0" />
        <parent link="chassis" />
        <child link="right_wheel_steering" />
        <axis xyz="0 1 0" />
        <dynamics damping="0.2" />
        <limit effort="10000.0" lower="-0.57" upper="0.57" velocity="30"/>
    </joint>

    
    <link name="front_left_wheel">
        <collision>
            <geometry>
                <cylinder length="${wheel_width}" radius="${wheel_radius}" />
            </geometry>
        </collision>
        <visual>
            <geometry>
                <cylinder length="${wheel_width}" radius="${wheel_radius}" />
            </geometry>
            <material name="Black" />
        </visual>
        <inertial>
            <mass value="11.3" />
            <inertia ixx="0.26" ixy="0.0" ixz="0.0" iyy="0.26" iyz="0.0" izz="0.51" />
        </inertial>
    </link>

    <joint name="front_left_wheel_joint" type="continuous">
        <origin xyz="0 0 0" rpy="0 0 0" />
        <parent link="left_wheel_steering" />
        <child link="front_left_wheel" />
        <axis xyz="0 0 1" />
        <dynamics damping="0.2" />
    </joint>

   
    <link name="front_right_wheel">
        <collision>
            <geometry>
                <cylinder length="${wheel_width}" radius="${wheel_radius}" />
            </geometry>
        </collision>
        <visual>
            <geometry>
                <cylinder length="${wheel_width}" radius="${wheel_radius}"/>
            </geometry>
            <material name="Black" />
        </visual>
        <inertial>
            <mass value="11.3" />
             <inertia ixx="0.026" ixy="0.0" ixz="0.0" iyy="0.026" iyz="0.0" izz="0.051"/>
        </inertial>
    </link>

    <joint name="front_right_wheel_joint" type="continuous">
        <origin xyz="0 0 0" rpy="0 0 0" />
        <parent link="right_wheel_steering" />
        <child link="front_right_wheel" />
        <axis xyz="0 0 1" />
        <dynamics damping="0.2" />
    </joint>


    <xacro:unless value="$(arg sim_mode)">
    
        <ros2_control name="OnyCroit" type="system">
        <hardware>
            <plugin>ackerman_robot/DiffDriveArduinoHardware</plugin>
            <param name="front_left_wheel_name">left_wheel_steering_joint</param>
            <param name="front_right_wheel_name">right_wheel_steering_joint</param>
            <param name="rear_left_wheel_name">rear_left_wheel_joint</param>
            <param name="rear_right_wheel_name">rear_right_wheel_joint</param>
            <param name="loop_rate">30</param>
            <param name="device">/dev/ttyACM0</param>
            <param name="baud_rate">115200</param>
            <param name="timeout_ms">1000</param>
            <param name="enc_counts_per_rev">3436</param>
            <param name="pid_p">20</param>
            <param name="pid_d">12</param>
            <param name="pid_i">0</param>
            <param name="pid_o">50</param>
        </hardware>
        
        <joint name="rear_left_wheel_joint">
        <command_interface name="velocity" />
        <state_interface name="velocity" />
        <state_interface name="position" />
        </joint>

            <joint name="rear_right_wheel_joint">
            <command_interface name="velocity" />
            <state_interface name="velocity" />
            <state_interface name="position" />
            </joint>
            
            <joint name="left_wheel_steering_joint">
            <command_interface name="position" />
            <state_interface name="position" />
            </joint>
            
            <joint name="right_wheel_steering_joint">
            <command_interface name="position" />
            <state_interface name="position" />
            </joint>
        </ros2_control>
    </xacro:unless>

  <xacro:if value="$(arg sim_mode)">


    <ros2_control name="GazeboSystem" type="system">
        <hardware>
        <plugin>gz_ros2_control/GazeboSimSystem</plugin>
        </hardware>
        <joint name="rear_left_wheel_joint">
        <command_interface name="velocity" />
        <state_interface name="velocity" />
        <state_interface name="position" />
        </joint>
        <joint name="rear_right_wheel_joint">
        <command_interface name="velocity" />
        <state_interface name="velocity" />
        <state_interface name="position" />
        </joint>
        <joint name="left_wheel_steering_joint">
        <command_interface name="position" />
        <state_interface name="position" />
        </joint>
        <joint name="right_wheel_steering_joint">
        <command_interface name="position" />
        <state_interface name="position" />
        </joint>
    </ros2_control>

        <gazebo>
            <plugin filename="gz_ros2_control-system" name="gz_ros2_control::GazeboSimROS2ControlPlugin">
                <parameters>$(find ackerman_robot)/config/ackermann_controller.yaml</parameters>
            </plugin>
        </gazebo>
    </xacro:if>
</robot>
