<sdf version='1.11'>
  <model name='ackermann_steering_vehicle'>
    <link name='body_link'>
      <inertial>
        <pose>1.7999999640000012e-08 1.4999999700000019e-09 2.2499999550000009e-08 0 0 0</pose>
        <mass>1000.0000199999999</mass>
        <inertia>
          <ixx>104.16669701666611</ixx>
          <ixy>-1.3499999730000011e-06</ixy>
          <ixz>-2.024999959500001e-05</ixz>
          <iyy>354.1667129916658</iyy>
          <iyz>-1.124999966250001e-06</iyz>
          <izz>416.6666850916663</izz>
        </inertia>
      </inertial>
      <collision name='body_link_collision'>
        <pose>0 0 0 0 0 0</pose>
        <geometry>
          <box>
            <size>2 1 0.5</size>
          </box>
        </geometry>
        <surface>
          <contact>
            <ode/>
          </contact>
          <friction>
            <ode>
              <mu>0.0001</mu>
              <mu2>0.0001</mu2>
            </ode>
          </friction>
        </surface>
      </collision>
      <collision name='body_link_fixed_joint_lump__camera_stick_link_collision_1'>
        <pose>0.90000000000000002 0.14999999999999999 0.75 0 0 0</pose>
        <geometry>
          <box>
            <size>0.20000000000000001 0.20000000000000001 1.5</size>
          </box>
        </geometry>
      </collision>
      <collision name='body_link_fixed_joint_lump__camera_link_collision_2'>
        <pose>0.90000000000000002 0 1.5 0 0.10000000000000001 0</pose>
        <geometry>
          <box>
            <size>0.10000000000000001 0.10000000000000001 0.10000000000000001</size>
          </box>
        </geometry>
      </collision>
      <visual name='body_link_visual'>
        <pose>0 0 0 0 0 0</pose>
        <geometry>
          <box>
            <size>2 1 0.5</size>
          </box>
        </geometry>
        <material>
          <diffuse>0.3125 0.3125 0.3125 1</diffuse>
          <ambient>0.3125 0.3125 0.3125 1</ambient>
        </material>
      </visual>
      <visual name='body_link_fixed_joint_lump__camera_stick_link_visual_1'>
        <pose>0.90000000000000002 0.14999999999999999 0.75 0 0 0</pose>
        <geometry>
          <box>
            <size>0.20000000000000001 0.20000000000000001 1.5</size>
          </box>
        </geometry>
        <material>
          <diffuse>0.3125 0.3125 0.3125 1</diffuse>
          <ambient>0.3125 0.3125 0.3125 1</ambient>
        </material>
      </visual>
      <visual name='body_link_fixed_joint_lump__camera_link_visual_2'>
        <pose>0.90000000000000002 0 1.5 0 0.10000000000000001 0</pose>
        <geometry>
          <box>
            <size>0.10000000000000001 0.10000000000000001 0.10000000000000001</size>
          </box>
        </geometry>
        <material>
          <diffuse>0 0 0 1</diffuse>
          <ambient>0 0 0 1</ambient>
        </material>
      </visual>
    </link>
    <joint name='front_left_steering_joint' type='revolute'>
      <pose relative_to='body_link'>0.69999999999999996 0.55000000000000004 -0.14999999999999999 0 0 0</pose>
      <parent>body_link</parent>
      <child>front_left_steering_link</child>
      <axis>
        <xyz>0 0 1</xyz>
        <limit>
          <lower>-0.61080000000000001</lower>
          <upper>0.61080000000000001</upper>
          <effort>1</effort>
          <velocity>1.5707960000000001</velocity>
        </limit>
        <dynamics>
          <damping>0.10000000000000001</damping>
          <friction>0.10000000000000001</friction>
          <spring_reference>0</spring_reference>
          <spring_stiffness>0</spring_stiffness>
        </dynamics>
      </axis>
    </joint>
    <link name='front_left_steering_link'>
      <pose relative_to='front_left_steering_joint'>0 0 0 0 0 0</pose>
      <inertial>
        <pose>0 0 0 1.5707949999999999 0 0</pose>
        <mass>0.01</mass>
        <inertia>
          <ixx>0</ixx>
          <ixy>0</ixy>
          <ixz>0</ixz>
          <iyy>0</iyy>
          <iyz>0</iyz>
          <izz>0</izz>
        </inertia>
      </inertial>
      <collision name='front_left_steering_link_collision'>
        <pose>0 0 0 1.5707949999999999 0 0</pose>
        <geometry>
          <cylinder>
            <length>0.001</length>
            <radius>0.01</radius>
          </cylinder>
        </geometry>
      </collision>
      <visual name='front_left_steering_link_visual'>
        <pose>0 0 0 1.5707949999999999 0 0</pose>
        <geometry>
          <cylinder>
            <length>0.001</length>
            <radius>0.01</radius>
          </cylinder>
        </geometry>
        <material>
          <diffuse>0 0 0 1</diffuse>
          <ambient>0 0 0 1</ambient>
        </material>
      </visual>
    </link>
    <joint name='front_left_wheel_joint' type='revolute'>
      <pose relative_to='front_left_steering_link'>0 0 0 0 0 0</pose>
      <parent>front_left_steering_link</parent>
      <child>front_left_wheel_link</child>
      <axis>
        <xyz>0 1 0</xyz>
        <limit>
          <effort>10</effort>
          <velocity>3.333333333333333</velocity>
          <lower>-inf</lower>
          <upper>inf</upper>
        </limit>
        <dynamics>
          <damping>0.10000000000000001</damping>
          <friction>0.10000000000000001</friction>
          <spring_reference>0</spring_reference>
          <spring_stiffness>0</spring_stiffness>
        </dynamics>
      </axis>
    </joint>
    <link name='front_left_wheel_link'>
      <pose relative_to='front_left_wheel_joint'>0 0 0 0 0 0</pose>
      <inertial>
        <pose>0 0 0 1.5707949999999999 0 0</pose>
        <mass>28.274333850000001</mass>
        <inertia>
          <ixx>0.65973445649999984</ixx>
          <ixy>0</ixy>
          <ixz>0</ixz>
          <iyy>0.65973445649999984</iyy>
          <iyz>0</iyz>
          <izz>1.27234502325</izz>
        </inertia>
      </inertial>
      <collision name='front_left_wheel_link_collision'>
        <pose>0 0 0 1.5707949999999999 0 0</pose>
        <geometry>
          <cylinder>
            <length>0.10000000000000001</length>
            <radius>0.29999999999999999</radius>
          </cylinder>
        </geometry>
        <surface>
          <contact>
            <ode/>
          </contact>
          <friction>
            <ode>
              <mu>100</mu>
              <mu2>100</mu2>
            </ode>
          </friction>
        </surface>
      </collision>
      <visual name='front_left_wheel_link_visual'>
        <pose>0 0 0 1.5707949999999999 0 0</pose>
        <geometry>
          <cylinder>
            <length>0.10000000000000001</length>
            <radius>0.29999999999999999</radius>
          </cylinder>
        </geometry>
        <material>
          <diffuse>0 0 0 1</diffuse>
          <ambient>0 0 0 1</ambient>
        </material>
      </visual>
    </link>
    <joint name='front_right_steering_joint' type='revolute'>
      <pose relative_to='body_link'>0.69999999999999996 -0.55000000000000004 -0.14999999999999999 0 0 0</pose>
      <parent>body_link</parent>
      <child>front_right_steering_link</child>
      <axis>
        <xyz>0 0 1</xyz>
        <limit>
          <lower>-0.61080000000000001</lower>
          <upper>0.61080000000000001</upper>
          <effort>1</effort>
          <velocity>1.5707960000000001</velocity>
        </limit>
        <dynamics>
          <damping>0.10000000000000001</damping>
          <friction>0.10000000000000001</friction>
          <spring_reference>0</spring_reference>
          <spring_stiffness>0</spring_stiffness>
        </dynamics>
      </axis>
    </joint>
    <link name='front_right_steering_link'>
      <pose relative_to='front_right_steering_joint'>0 0 0 0 0 0</pose>
      <inertial>
        <pose>0 0 0 1.5707949999999999 0 0</pose>
        <mass>0.01</mass>
        <inertia>
          <ixx>0</ixx>
          <ixy>0</ixy>
          <ixz>0</ixz>
          <iyy>0</iyy>
          <iyz>0</iyz>
          <izz>0</izz>
        </inertia>
      </inertial>
      <collision name='front_right_steering_link_collision'>
        <pose>0 0 0 1.5707949999999999 0 0</pose>
        <geometry>
          <cylinder>
            <length>0.001</length>
            <radius>0.01</radius>
          </cylinder>
        </geometry>
      </collision>
      <visual name='front_right_steering_link_visual'>
        <pose>0 0 0 1.5707949999999999 0 0</pose>
        <geometry>
          <cylinder>
            <length>0.001</length>
            <radius>0.01</radius>
          </cylinder>
        </geometry>
        <material>
          <diffuse>0 0 0 1</diffuse>
          <ambient>0 0 0 1</ambient>
        </material>
      </visual>
    </link>
    <joint name='front_right_wheel_joint' type='revolute'>
      <pose relative_to='front_right_steering_link'>0 0 0 0 0 0</pose>
      <parent>front_right_steering_link</parent>
      <child>front_right_wheel_link</child>
      <axis>
        <xyz>0 1 0</xyz>
        <limit>
          <effort>10</effort>
          <velocity>3.333333333333333</velocity>
          <lower>-inf</lower>
          <upper>inf</upper>
        </limit>
        <dynamics>
          <damping>0.10000000000000001</damping>
          <friction>0.10000000000000001</friction>
          <spring_reference>0</spring_reference>
          <spring_stiffness>0</spring_stiffness>
        </dynamics>
      </axis>
    </joint>
    <link name='front_right_wheel_link'>
      <pose relative_to='front_right_wheel_joint'>0 0 0 0 0 0</pose>
      <inertial>
        <pose>0 0 0 1.5707949999999999 0 0</pose>
        <mass>28.274333850000001</mass>
        <inertia>
          <ixx>0.65973445649999984</ixx>
          <ixy>0</ixy>
          <ixz>0</ixz>
          <iyy>0.65973445649999984</iyy>
          <iyz>0</iyz>
          <izz>1.27234502325</izz>
        </inertia>
      </inertial>
      <collision name='front_right_wheel_link_collision'>
        <pose>0 0 0 1.5707949999999999 0 0</pose>
        <geometry>
          <cylinder>
            <length>0.10000000000000001</length>
            <radius>0.29999999999999999</radius>
          </cylinder>
        </geometry>
        <surface>
          <contact>
            <ode/>
          </contact>
          <friction>
            <ode>
              <mu>100</mu>
              <mu2>100</mu2>
            </ode>
          </friction>
        </surface>
      </collision>
      <visual name='front_right_wheel_link_visual'>
        <pose>0 0 0 1.5707949999999999 0 0</pose>
        <geometry>
          <cylinder>
            <length>0.10000000000000001</length>
            <radius>0.29999999999999999</radius>
          </cylinder>
        </geometry>
        <material>
          <diffuse>0 0 0 1</diffuse>
          <ambient>0 0 0 1</ambient>
        </material>
      </visual>
    </link>
    <joint name='rear_left_wheel_joint' type='revolute'>
      <pose relative_to='body_link'>-0.69999999999999996 0.55000000000000004 -0.14999999999999999 0 0 0</pose>
      <parent>body_link</parent>
      <child>rear_left_wheel_link</child>
      <axis>
        <xyz>0 1 0</xyz>
        <limit>
          <effort>10</effort>
          <velocity>3.333333333333333</velocity>
          <lower>-inf</lower>
          <upper>inf</upper>
        </limit>
        <dynamics>
          <damping>0.10000000000000001</damping>
          <friction>0.10000000000000001</friction>
          <spring_reference>0</spring_reference>
          <spring_stiffness>0</spring_stiffness>
        </dynamics>
      </axis>
    </joint>
    <link name='rear_left_wheel_link'>
      <pose relative_to='rear_left_wheel_joint'>0 0 0 0 0 0</pose>
      <inertial>
        <pose>0 0 0 1.5707949999999999 0 0</pose>
        <mass>2</mass>
        <inertia>
          <ixx>0.65973445649999984</ixx>
          <ixy>0</ixy>
          <ixz>0</ixz>
          <iyy>0.65973445649999984</iyy>
          <iyz>0</iyz>
          <izz>1.27234502325</izz>
        </inertia>
      </inertial>
      <collision name='rear_left_wheel_link_collision'>
        <pose>0 0 0 1.5707949999999999 0 0</pose>
        <geometry>
          <cylinder>
            <length>0.10000000000000001</length>
            <radius>0.29999999999999999</radius>
          </cylinder>
        </geometry>
        <surface>
          <contact>
            <ode/>
          </contact>
          <friction>
            <ode>
              <mu>100</mu>
              <mu2>100</mu2>
            </ode>
          </friction>
        </surface>
      </collision>
      <visual name='rear_left_wheel_link_visual'>
        <pose>0 0 0 1.5707949999999999 0 0</pose>
        <geometry>
          <cylinder>
            <length>0.10000000000000001</length>
            <radius>0.29999999999999999</radius>
          </cylinder>
        </geometry>
        <material>
          <diffuse>0 0 0 1</diffuse>
          <ambient>0 0 0 1</ambient>
        </material>
      </visual>
    </link>
    <joint name='rear_right_wheel_joint' type='revolute'>
      <pose relative_to='body_link'>-0.69999999999999996 -0.55000000000000004 -0.14999999999999999 0 0 0</pose>
      <parent>body_link</parent>
      <child>rear_right_wheel_link</child>
      <axis>
        <xyz>0 1 0</xyz>
        <limit>
          <effort>10</effort>
          <velocity>3.333333333333333</velocity>
          <lower>-inf</lower>
          <upper>inf</upper>
        </limit>
        <dynamics>
          <damping>0.10000000000000001</damping>
          <friction>0.10000000000000001</friction>
          <spring_reference>0</spring_reference>
          <spring_stiffness>0</spring_stiffness>
        </dynamics>
      </axis>
    </joint>
    <link name='rear_right_wheel_link'>
      <pose relative_to='rear_right_wheel_joint'>0 0 0 0 0 0</pose>
      <inertial>
        <pose>0 0 0 1.5707949999999999 0 0</pose>
        <mass>2</mass>
        <inertia>
          <ixx>0.65973445649999984</ixx>
          <ixy>0</ixy>
          <ixz>0</ixz>
          <iyy>0.65973445649999984</iyy>
          <iyz>0</iyz>
          <izz>1.27234502325</izz>
        </inertia>
      </inertial>
      <collision name='rear_right_wheel_link_collision'>
        <pose>0 0 0 1.5707949999999999 0 0</pose>
        <geometry>
          <cylinder>
            <length>0.10000000000000001</length>
            <radius>0.29999999999999999</radius>
          </cylinder>
        </geometry>
        <surface>
          <contact>
            <ode/>
          </contact>
          <friction>
            <ode>
              <mu>100</mu>
              <mu2>100</mu2>
            </ode>
          </friction>
        </surface>
      </collision>
      <visual name='rear_right_wheel_link_visual'>
        <pose>0 0 0 1.5707949999999999 0 0</pose>
        <geometry>
          <cylinder>
            <length>0.10000000000000001</length>
            <radius>0.29999999999999999</radius>
          </cylinder>
        </geometry>
        <material>
          <diffuse>0 0 0 1</diffuse>
          <ambient>0 0 0 1</ambient>
        </material>
      </visual>
    </link>
    <plugin name='gz::sim::systems::TriggeredPublisher' filename='gz-sim-triggered-publisher-system'>
      <input topic='/keyboard/keypress' type='gz.msgs.Int32'>
        <match field='data'>16777235</match>
      </input>
      <output topic='/cmd_vel' type='gz.msgs.Twist'>linear: {x: 0.5}, angular: {z: 0.0}</output>
    </plugin>
    <plugin name='gz::sim::systems::TriggeredPublisher' filename='gz-sim-triggered-publisher-system'>
      <input topic='/keyboard/keypress' type='gz.msgs.Int32'>
        <match field='data'>16777237</match>
      </input>
      <output topic='/cmd_vel' type='gz.msgs.Twist'>linear: {x: -0.5}, angular: {z: 0}</output>
    </plugin>
    <plugin name='gz::sim::systems::TriggeredPublisher' filename='gz-sim-triggered-publisher-system'>
      <input topic='/keyboard/keypress' type='gz.msgs.Int32'>
        <match field='data'>16777234</match>
      </input>
      <output topic='/cmd_vel' type='gz.msgs.Twist'>linear: {x: 0}, angular: {z: 0.5}</output>
    </plugin>
    <plugin name='gz::sim::systems::TriggeredPublisher' filename='gz-sim-triggered-publisher-system'>
      <input topic='/keyboard/keypress' type='gz.msgs.Int32'>
        <match field='data'>16777236</match>
      </input>
      <output topic='/cmd_vel' type='gz.msgs.Twist'>linear: {x: 0}, angular: {z: -0.5}</output>
    </plugin>
    <plugin name='gz::sim::systems::Physics' filename='gz-sim-physics-system'/>
    <plugin name='gz::sim::systems::UserCommands' filename='gz-sim-user-commands-system'/>
    <plugin name='gz::sim::systems::SceneBroadcaster' filename='gz-sim-scene-broadcaster-system'/>
    <frame name='camera_joint' attached_to='camera_stick_link'>
      <pose>0 -0.14999999999999999 0.75 0 0.10000000000000001 0</pose>
    </frame>
    <frame name='camera_link' attached_to='camera_joint'>
      <pose>0 0 0 0 0 0</pose>
    </frame>
    <frame name='camera_stick_joint' attached_to='body_link'>
      <pose>0.90000000000000002 0.14999999999999999 0.75 0 0 0</pose>
    </frame>
    <frame name='camera_stick_link' attached_to='camera_stick_joint'>
      <pose>0 0 0 0 0 0</pose>
    </frame>
    <physics name='1ms' type='ignored'>
      <max_step_size>0.001</max_step_size>
      <real_time_factor>1.0</real_time_factor>
    </physics>
  </model>
</sdf>
